<?xml version="1.0" encoding="utf-8"?>
<!-- This URDF was automatically created by SolidWorks to URDF Exporter! Originally created by Stephen Brawner (brawner@gmail.com) 
     Commit Version: 1.6.0-4-g7f85cfe  Build Version: 1.6.7995.38578
     For more information, please see http://wiki.ros.org/sw_urdf_exporter -->
<robot
  name="Edu_v4">
  <link
    name="base_link">
    <inertial>
      <origin xyz="-0.00589457 0.00113829 -0.05282656"/>
      <mass value="2.56800000"/>
      <inertia ixx="0.01981432" ixy="-0.00000000" ixz="0.00057678" iyy="0.00625385" iyz="-0.00000000" izz="0.01642957"/>
    </inertial>
    <visual>
      <origin
        xyz="0 0 0"
        rpy="0 0 0" />
      <geometry>
        <mesh
          filename="../meshes/base_link.STL" />
      </geometry>
      <material
        name="">
        <color
          rgba="0.756862745098039 0.768627450980392 0.752941176470588 1" />
      </material>
    </visual>
    <collision>
      <origin
        xyz="0 0 0"
        rpy="0 0 0" />
      <geometry>
        <mesh
          filename="../meshes/base_link.STL" />
      </geometry>
    </collision>
  </link>
  <link
    name="left_shoulder_link">
    <inertial>
      <origin xyz="0.02319287 0.00232951 0.00696198"/>
      <mass value="0.15000000"/>
      <inertia ixx="0.00002297" ixy="-0.00003393" ixz="-0.00000368" iyy="0.00037816" iyz="-0.00000035" izz="0.00039819"/>
    </inertial>
    <visual>
      <origin
        xyz="0 0 0"
        rpy="0 0 0" />
      <geometry>
        <mesh
          filename="../meshes/left_shoulder_link.STL" />
      </geometry>
      <material
        name="">
        <color
          rgba="0.823529411764706 0.823529411764706 1 1" />
      </material>
    </visual>
    <collision>
      <origin
        xyz="0 0 0"
        rpy="0 0 0" />
      <geometry>
        <mesh
          filename="../meshes/left_shoulder_link.STL" />
      </geometry>
    </collision>
  </link>
  <joint
    name="left_shoulder_joint"
    type="revolute">
    <origin
      xyz="-0.004 0.136 -0.08"
      rpy="1.5708 0 -3.1416" />
    <parent
      link="base_link" />
    <child
      link="left_shoulder_link" />
    <axis
      xyz="0 0 1" />
    <limit
      lower="-1.2754"
      upper="0"
      effort="12"
      velocity="30" />
  </joint>
  <link
    name="left_leg_link">
    <inertial>
      <origin xyz="-0.11633099 -0.08320597 0.00347048"/>
      <mass value="0.44700000"/>
      <inertia ixx="0.00065381" ixy="-0.00064252" ixz="0.00005613" iyy="0.00108827" iyz="0.00004032" izz="0.00166657"/>
    </inertial>
    <visual>
      <origin
        xyz="0 0 0"
        rpy="0 0 0" />
      <geometry>
        <mesh
          filename="../meshes/left_leg_link.STL" />
      </geometry>
      <material
        name="">
        <color
          rgba="0.823529411764706 0.823529411764706 1 1" />
      </material>
    </visual>
    <collision>
      <origin
        xyz="0 0 0"
        rpy="0 0 0" />
      <geometry>
        <mesh
          filename="../meshes/left_leg_link.STL" />
      </geometry>
    </collision>
  </link>
  <joint
    name="left_leg_joint"
    type="revolute">
    <origin
      xyz="0.15929 0.015078 0.00045"
      rpy="0 0 0" />
    <parent
      link="left_shoulder_link" />
    <child
      link="left_leg_link" />
    <axis
      xyz="0 0 1" />
    <limit
      lower="0"
      upper="2.618"
      effort="12"
      velocity="30" />
  </joint>
  <link
    name="left_wheel_link">
    <inertial>
      <origin xyz="-0.00010105 0.00002337 0.01451599"/>
      <mass value="0.54500000"/>
      <inertia ixx="0.00136908" ixy="-0.00000000" ixz="0.00000000" iyy="0.00136908" iyz="0.00000000" izz="0.00263239"/>
    </inertial>
    <visual>
      <origin
        xyz="0 0 0"
        rpy="0 0 0" />
      <geometry>
        <mesh
          filename="../meshes/left_wheel_link.STL" />
      </geometry>
      <material
        name="">
        <color
          rgba="0.792156862745098 0.819607843137255 0.933333333333333 1" />
      </material>
    </visual>
    <collision>
      <origin
        xyz="0 0 0"
        rpy="0 0 0" />
      <geometry>
        <mesh
          filename="../meshes/left_wheel_link.STL" />
      </geometry>
    </collision>
  </link>
  <joint
    name="left_wheel_joint"
    type="continuous">
    <origin
      xyz="-0.13 -0.093274 0.0315"
      rpy="0 0 0" />
    <parent
      link="left_leg_link" />
    <child
      link="left_wheel_link" />
    <axis
      xyz="0 0 1" />
    <limit
      effort="12"
      velocity="30" />
  </joint>
  <link
    name="right_shoulder_link">
    <inertial>
      <origin xyz="-0.02321802 0.00206382 0.00696198"/>
      <mass value="0.15000000"/>
      <inertia ixx="0.00002297" ixy="0.00003393" ixz="0.00000368" iyy="0.00037816" iyz="-0.00000035" izz="0.00039819"/>
    </inertial>
    <visual>
      <origin
        xyz="0 0 0"
        rpy="0 0 0" />
      <geometry>
        <mesh
          filename="../meshes/right_shoulder_link.STL" />
      </geometry>
      <material
        name="">
        <color
          rgba="0.823529411764706 0.823529411764706 1 1" />
      </material>
    </visual>
    <collision>
      <origin
        xyz="0 0 0"
        rpy="0 0 0" />
      <geometry>
        <mesh
          filename="../meshes/right_shoulder_link.STL" />
      </geometry>
    </collision>
  </link>
  <joint
    name="right_shoulder_joint"
    type="revolute">
    <origin
      xyz="-0.004 -0.136 -0.08"
      rpy="1.5708 0 0" />
    <parent
      link="base_link" />
    <child
      link="right_shoulder_link" />
    <axis
      xyz="0 0 -1" />
    <limit
      lower="-1.2754"
      upper="0"
      effort="12"
      velocity="30" />
  </joint>
  <link
    name="right_leg_link">
    <inertial>
      <origin xyz="0.11608679 -0.08355273 0.00347179"/>
      <mass value="0.44700000"/>
      <inertia ixx="0.00065376" ixy="0.00064250" ixz="-0.00005617" iyy="0.00108832" iyz="0.00004026" izz="0.00166657"/>
    </inertial>
    <visual>
      <origin
        xyz="0 0 0"
        rpy="0 0 0" />
      <geometry>
        <mesh
          filename="../meshes/right_leg_link.STL" />
      </geometry>
      <material
        name="">
        <color
          rgba="0.823529411764706 0.823529411764706 1 1" />
      </material>
    </visual>
    <collision>
      <origin
        xyz="0 0 0"
        rpy="0 0 0" />
      <geometry>
        <mesh
          filename="../meshes/right_leg_link.STL" />
      </geometry>
    </collision>
  </link>
  <joint
    name="right_leg_joint"
    type="revolute">
    <origin
      xyz="-0.15929 0.015078 0.00045"
      rpy="0 0 0" />
    <parent
      link="right_shoulder_link" />
    <child
      link="right_leg_link" />
    <axis
      xyz="0 0 -1" />
    <limit
      lower="0"
      upper="2.618"
      effort="12"
      velocity="30" />
  </joint>
  <link
    name="right_wheel_link">
    <inertial>
      <origin xyz="-0.00001023 0.00010322 0.01451599"/>
      <mass value="0.54500000"/>
      <inertia ixx="0.00136908" ixy="0.00000000" ixz="0.00000000" iyy="0.00136908" iyz="-0.00000000" izz="0.00263239"/>
    </inertial>
    <visual>
      <origin
        xyz="0 0 0"
        rpy="0 0 0" />
      <geometry>
        <mesh
          filename="../meshes/right_wheel_link.STL" />
      </geometry>
      <material
        name="">
        <color
          rgba="0.792156862745098 0.819607843137255 0.933333333333333 1" />
      </material>
    </visual>
    <collision>
      <origin
        xyz="0 0 0"
        rpy="0 0 0" />
      <geometry>
        <mesh
          filename="../meshes/right_wheel_link.STL" />
      </geometry>
    </collision>
  </link>
  <joint
    name="right_wheel_joint"
    type="continuous">
    <origin
      xyz="0.13 -0.093274 0.0315"
      rpy="0 0 0" />
    <parent
      link="right_leg_link" />
    <child
      link="right_wheel_link" />
    <axis
      xyz="0 0 -1" />
    <limit
      effort="12"
      velocity="30" />
  </joint>
  <!-- <link
    name="left_upper_link">
    <inertial>
      <origin xyz="0.07991445 -0.00369865 -0.00000000"/>
      <mass value="0.04273000"/>
      <inertia ixx="0.00000120" ixy="0.00000481" ixz="-0.00000000" iyy="0.00010494" iyz="0.00000000" izz="0.00010569"/>
    </inertial>
    <visual>
      <origin
        xyz="0 0 0"
        rpy="0 0 0" />
      <geometry>
        <mesh
          filename="../meshes/left_upper_link.STL" />
      </geometry>
      <material
        name="">
        <color
          rgba="0.823529411764706 0.823529411764706 1 1" />
      </material>
    </visual>
    <collision>
      <origin
        xyz="0 0 0"
        rpy="0 0 0" />
      <geometry>
        <mesh
          filename="../meshes/left_upper_link.STL" />
      </geometry>
    </collision>
  </link>
  <joint
    name="left_upper_joint"
    type="revolute">
    <origin
      xyz="-0.052209 0.143 -0.022547"
      rpy="1.5708 0 3.1416" />
    <parent
      link="base_link" />
    <child
      link="left_upper_link" />
    <axis
      xyz="0 0 1" />
    <limit
      lower="-1.0754"
      upper="1.0754"
      effort="12"
      velocity="30" />
  </joint> -->
  <!-- <link
    name="right_upper_link">
    <inertial>
      <origin xyz="-0.07991445 -0.00369865 0.00000000"/>
      <mass value="0.04273000"/>
      <inertia ixx="0.00000120" ixy="-0.00000481" ixz="-0.00000000" iyy="0.00010494" iyz="-0.00000000" izz="0.00010569"/>
    </inertial>
    <visual>
      <origin
        xyz="0 0 0"
        rpy="0 0 0" />
      <geometry>
        <mesh
          filename="../meshes/right_upper_link.STL" />
      </geometry>
      <material
        name="">
        <color
          rgba="0.823529411764706 0.823529411764706 1 1" />
      </material>
    </visual>
    <collision>
      <origin
        xyz="0 0 0"
        rpy="0 0 0" />
      <geometry>
        <mesh
          filename="../meshes/right_upper_link.STL" />
      </geometry>
    </collision>
  </link>
  <joint
    name="right_upper_joint"
    type="revolute">
    <origin
      xyz="-0.052209 -0.144 -0.022547"
      rpy="1.5708 0 0" />
    <parent
      link="base_link" />
    <child
      link="right_upper_link" />
    <axis
      xyz="0 0 -1" />
    <limit
      lower="-1.0754"
      upper="1.0754"
      effort="12"
      velocity="30" />
  </joint> -->
  <link
    name="front_cover_link">
    <inertial>
      <origin xyz="-0.01450628 -0.00000001 -0.00353267"/>
      <mass value="0.19400000"/>
      <inertia ixx="0.00111820" ixy="0.00000000" ixz="-0.00000000" iyy="0.00041282" iyz="0.00000000" izz="0.00074533"/>
    </inertial>
    <visual>
      <origin
        xyz="0 0 0"
        rpy="0 0 0" />
      <geometry>
        <mesh
          filename="../meshes/front_cover_link.STL" />
      </geometry>
      <material
        name="">
        <color
          rgba="0.792156862745098 0.819607843137255 0.933333333333333 1" />
      </material>
    </visual>
    <collision>
      <origin
        xyz="0 0 0"
        rpy="0 0 0" />
      <geometry>
        <mesh
          filename="../meshes/front_cover_link.STL" />
      </geometry>
    </collision>
  </link>
  <joint
    name="front_cover_joint"
    type="fixed">
    <origin
      xyz="0.052 0 -0.078496"
      rpy="0 0 0" />
    <parent
      link="base_link" />
    <child
      link="front_cover_link" />
    <axis
      xyz="0 0 0" />
  </joint>
  <link
    name="rear_cover_link">
    <inertial>
      <origin xyz="0.04255973 -0.00349397 0.00235904"/>
      <mass value="0.49900000"/>
      <inertia ixx="0.00295846" ixy="0.00000000" ixz="0.00000000" iyy="0.00146584" iyz="-0.00000000" izz="0.00233337"/>
    </inertial>
    <visual>
      <origin
        xyz="0 0 0"
        rpy="0 0 0" />
      <geometry>
        <mesh
          filename="../meshes/rear_cover_link.STL" />
      </geometry>
      <material
        name="">
        <color
          rgba="0.792156862745098 0.819607843137255 0.933333333333333 1" />
      </material>
    </visual>
    <collision>
      <origin
        xyz="0 0 0"
        rpy="0 0 0" />
      <geometry>
        <mesh
          filename="../meshes/rear_cover_link.STL" />
      </geometry>
    </collision>
  </link>
  <joint
    name="rear_cover_joint"
    type="fixed">
    <origin
      xyz="-0.125999999999978 0 -0.0806008253486177"
      rpy="0 0 0" />
    <parent
      link="base_link" />
    <child
      link="rear_cover_link" />
    <axis
      xyz="0 0 0" />
  </joint>
</robot>